异常处理
===

## assert

```cpp
assert(expr);
```

对expr求值，如果表示为假，则输出信息并终止程序的执行。

```cpp
assert(word.size() > threshold);
//要求所有单词的长度大于某个阈值，否则退出。
```

## NDEBUG

assert依赖于NDEBUG的预处理变量的状态，如果定义了NDEBUG，assert失效。

## catch

## perror



## 异常的基本处理

```cpp
int myDevide(int a ,int b)
{
	if (b == 0)
	{
		//如果b是异常 抛出异常
		//return -1;

		//throw 1; 抛出int类型异常
		//throw 3.14; //抛出double类型异常  异常必须处理，如果不处理 就挂掉

		//throw 'a';
		
		//栈解旋
		//从try开始  到 throw 抛出异常之前  所有栈上的对象 都会被释放 这个过程称为栈解旋
		//构造和析构顺序相反
		Person p1;
		Person p2;

		throw myException(); //匿名对象

	}
	return a / b;
}



void test01()
{
	int a = 10;
	int b = 0;

	//int ret = myDevide(a, b); //早期如果返回-1 无法区分到底是结果还是异常

	//C++中异常处理

	try //试一试
	{
		myDevide(a, b);
	}
	catch (int) //捕获异常
	{
		cout << "int类型异常捕获" << endl;
	}
	catch (double)
	{
		//如果不想处理这个异常 ，可以继续向上抛出
		throw;
		cout << "double类型异常捕获" << endl;
	}
	catch (myException e)
	{
		e.printError();
	}
	catch (...)
	{
		cout << "其他类型异常捕获" << endl;
	}

}


int main(){

	try
	{
		test01();
	}
	catch (char ) //如果异常都没有处理，那么成员terminate函数，使程序中断
	{
		cout << "main 函数中 double类型异常捕获" << endl;
	}
	catch (...)
	{
		cout << "main函数中 其他类型异常捕获" << endl;
	}
	

	system("pause");
	return EXIT_SUCCESS;
}
```

## 自定义异常进行捕获

```cpp
class myException //自定义异常类
{
public:
	void printError()
	{
		cout << "自定义的异常" << endl;
	}
};

int myDevide(int a ,int b)
{
	if (b == 0)
	{
		throw myException(); //匿名对象
	}
	return a / b;
}
void test01()
{
	int a = 10;
	int b = 0;
    try //试一试
	{
		myDevide(a, b);
	}
	catch (myException e)
	{
		e.printError();
	}
	catch (...)
	{
		cout << "其他类型异常捕获" << endl;
	}
}
```

**栈解旋**

从try开始  到 throw 抛出异常之前  所有栈上的对象 都会被释放 这个过程称为栈解旋

**异常的接口声明**

```cpp
void func() throw int{
    
    throw 1;//只能抛出int
}
```

**异常变量的生命周期**

C++ 异常throw抛出一个匿名对象的地址，catch捕获类型为该匿名对象的指针，运行起来的效果是没有执行到catch下的异常输出，对象就已经被释放掉了，当改为抛出匿名对象时，catch处引用接收就不会发生这样的问题。

```cpp
class MyException
{
public:
	MyException()
	{
		cout << "MyException的默认构造" << endl;
	}
	MyException(const MyException & e)
	{
		cout << "MyException的拷贝构造" << endl;
	}
 
	~MyException()
	{
		cout << "MyException的析构调用" << endl;
	}
 
	void printError()
	{
		this->m_A = 100;
		cout << "error"  << m_A<< endl;
	}
 
	int m_A;
 
};
 
void doWork()
{
	throw  MyException();
}
 
void test01()
{
	try
	{
		doWork();
	}
	catch (MyException &e)
	{
        e->printError();
		
		cout << "捕获异常" << endl;
 
		//delete e; //靠自觉 释放对象
	}
}

int main(){
	test01();
	system("pause");
	return EXIT_SUCCESS;
}
```

**异常的多态**

**使用系统的标准异常**

```cpp
#include <stdexcept>
class Person
{
public:
	Person(string name, int age)
	{
		this->m_Name = name;
		//年龄做检测

		if (age < 0 || age > 200)
		{
			//抛出越界异常
			//throw  out_of_range("年龄越界了！");

			throw length_error("长度越界");
		}

	}


	string m_Name;
	int m_Age;
};

void test01()
{
	try
	{
		Person p("张三",300);
	}
	catch (out_of_range & e)
	{
		cout << e.what() << endl;
	}
	catch (length_error & e)
	{
		cout << e.what() << endl;
	}

}
```

**编写自己的异常类**

```cpp
#define _CRT_SECURE_NO_WARNINGS
#include<iostream>
using namespace std;
#include <string>

class MyOutOfRangeException:public exception
{

public:

	MyOutOfRangeException(string errorInfo)
	{
		this->m_ErrorInfo = errorInfo;
	}

	virtual  ~MyOutOfRangeException( )
	{

	}
	virtual const char *  what() const
	{
		//返回 错误信息
		//string 转 char *     .c_str()
		return this->m_ErrorInfo.c_str();
	}
	string m_ErrorInfo;
};
class Person
{
public:
	Person(string name, int age)
	{
		this->m_Name = name;
		//年龄做检测

		if (age < 0 || age > 200)
		{
			throw MyOutOfRangeException( string("我自己的年龄越界异常"));
		}
	}
	string m_Name;
	int m_Age;
};

void test01()
{
	try
	{
		Person p("张三", 300);
	}
	catch ( MyOutOfRangeException & e  )
	{
		cout << e.what() << endl;
	}
}
```

1. 继承于exception

2. 重写 虚析构  what（）
3. 内部维护以错误信息 字符串
4. 构造时候传入 错误信息字符串，what返回这个字符串

